2023-08-25 08:52:44 [INFO]: Shard ID None has connected to Gateway (Session ID: 40c0457069e5a12b67ac0afa3b4e74d9).
2023-08-25 08:52:46 [INFO]: Logged in as Berechti
2023-08-25 08:52:46 [INFO]: Bot ID 1125300916422193194
2023-08-25 08:52:46 [INFO]: Discord Version 2.3.2
2023-08-25 08:52:46 [INFO]: Python Version 3.11.4
2023-08-25 08:52:46 [INFO]: SQLite3 Version: 2.6.0
2023-08-25 08:52:46 [INFO]: Bot Version: Alpha 0.1
2023-08-25 08:52:46 [INFO]: Entwickler: Bitflux_
2023-08-25 08:52:46 [INFO]: Slash CMDs Synced 7 Commands
2023-08-25 09:07:48 [INFO]: WBCreateModal was succesfully
2023-08-25 09:08:14 [INFO]: Successfully connected to: e:\Discord\BerechtiBotServer\database\wb_storing.db
2023-08-25 09:08:14 [INFO]: The last entry, sorted by kw, was selected from the database
2023-08-25 09:08:14 [INFO]: The variable 'nr' + 1 was returned from select_kw_from_database
2023-08-25 09:08:14 [INFO]: Successfully connected to: e:\Discord\BerechtiBotServer\database\wb_storing.db
2023-08-25 09:08:14 [INFO]: id catch was succsesfully
2023-08-25 09:08:14 [INFO]: An entry was transferred to the database
2023-08-25 09:08:23 [INFO]: Successfully connected to: e:\Discord\BerechtiBotServer\database\wb_storing.db
2023-08-25 09:08:23 [INFO]: A match was found
2023-08-25 09:08:24 [INFO]: Entrys showed
2023-08-25 09:08:34 [ERROR]: Ignoring exception in command 'wb_search'
Traceback (most recent call last):
  File "C:\Users\WalkenNi\AppData\Local\Packages\PythonSoftwareFoundation.Python.3.11_qbz5n2kfra8p0\LocalCache\local-packages\Python311\site-packages\discord\app_commands\commands.py", line 827, in _do_call
    return await self._callback(self.binding, interaction, **params)  # type: ignore
           ^^^^^^^^^^^^^^^^^^^^^^^^^^^^^^^^^^^^^^^^^^^^^^^^^^^^^^^^^
  File "e:\Discord\BerechtiBotServer\cogs\wb_search.py", line 16, in wbsearch_command
    try:
TypeError: CustomLogger.log() missing 1 required positional argument: 'message'

The above exception was the direct cause of the following exception:

Traceback (most recent call last):
  File "C:\Users\WalkenNi\AppData\Local\Packages\PythonSoftwareFoundation.Python.3.11_qbz5n2kfra8p0\LocalCache\local-packages\Python311\site-packages\discord\app_commands\tree.py", line 1248, in _call
    await command._invoke_with_namespace(interaction, namespace)
  File "C:\Users\WalkenNi\AppData\Local\Packages\PythonSoftwareFoundation.Python.3.11_qbz5n2kfra8p0\LocalCache\local-packages\Python311\site-packages\discord\app_commands\commands.py", line 853, in _invoke_with_namespace
    return await self._do_call(interaction, transformed_values)
           ^^^^^^^^^^^^^^^^^^^^^^^^^^^^^^^^^^^^^^^^^^^^^^^^^^^^
  File "C:\Users\WalkenNi\AppData\Local\Packages\PythonSoftwareFoundation.Python.3.11_qbz5n2kfra8p0\LocalCache\local-packages\Python311\site-packages\discord\app_commands\commands.py", line 842, in _do_call
    raise CommandInvokeError(self, e) from e
discord.app_commands.errors.CommandInvokeError: Command 'wb_search' raised an exception: TypeError: CustomLogger.log() missing 1 required positional argument: 'message'
2023-08-25 09:09:30 [ERROR]: Ignoring exception in command 'wb_search'
Traceback (most recent call last):
  File "C:\Users\WalkenNi\AppData\Local\Packages\PythonSoftwareFoundation.Python.3.11_qbz5n2kfra8p0\LocalCache\local-packages\Python311\site-packages\discord\app_commands\commands.py", line 827, in _do_call
    return await self._callback(self.binding, interaction, **params)  # type: ignore
           ^^^^^^^^^^^^^^^^^^^^^^^^^^^^^^^^^^^^^^^^^^^^^^^^^^^^^^^^^
  File "e:\Discord\BerechtiBotServer\cogs\wb_search.py", line 16, in wbsearch_command
    try:
TypeError: CustomLogger.log() missing 1 required positional argument: 'message'

The above exception was the direct cause of the following exception:

Traceback (most recent call last):
  File "C:\Users\WalkenNi\AppData\Local\Packages\PythonSoftwareFoundation.Python.3.11_qbz5n2kfra8p0\LocalCache\local-packages\Python311\site-packages\discord\app_commands\tree.py", line 1248, in _call
    await command._invoke_with_namespace(interaction, namespace)
  File "C:\Users\WalkenNi\AppData\Local\Packages\PythonSoftwareFoundation.Python.3.11_qbz5n2kfra8p0\LocalCache\local-packages\Python311\site-packages\discord\app_commands\commands.py", line 853, in _invoke_with_namespace
    return await self._do_call(interaction, transformed_values)
           ^^^^^^^^^^^^^^^^^^^^^^^^^^^^^^^^^^^^^^^^^^^^^^^^^^^^
  File "C:\Users\WalkenNi\AppData\Local\Packages\PythonSoftwareFoundation.Python.3.11_qbz5n2kfra8p0\LocalCache\local-packages\Python311\site-packages\discord\app_commands\commands.py", line 842, in _do_call
    raise CommandInvokeError(self, e) from e
discord.app_commands.errors.CommandInvokeError: Command 'wb_search' raised an exception: TypeError: CustomLogger.log() missing 1 required positional argument: 'message'
2023-08-25 09:11:09 [ERROR]: Ignoring exception in command 'wb_search'
Traceback (most recent call last):
  File "C:\Users\WalkenNi\AppData\Local\Packages\PythonSoftwareFoundation.Python.3.11_qbz5n2kfra8p0\LocalCache\local-packages\Python311\site-packages\discord\app_commands\commands.py", line 827, in _do_call
    return await self._callback(self.binding, interaction, **params)  # type: ignore
           ^^^^^^^^^^^^^^^^^^^^^^^^^^^^^^^^^^^^^^^^^^^^^^^^^^^^^^^^^
  File "e:\Discord\BerechtiBotServer\cogs\wb_search.py", line 16, in wbsearch_command
    try:
TypeError: CustomLogger.log() missing 1 required positional argument: 'message'

The above exception was the direct cause of the following exception:

Traceback (most recent call last):
  File "C:\Users\WalkenNi\AppData\Local\Packages\PythonSoftwareFoundation.Python.3.11_qbz5n2kfra8p0\LocalCache\local-packages\Python311\site-packages\discord\app_commands\tree.py", line 1248, in _call
    await command._invoke_with_namespace(interaction, namespace)
  File "C:\Users\WalkenNi\AppData\Local\Packages\PythonSoftwareFoundation.Python.3.11_qbz5n2kfra8p0\LocalCache\local-packages\Python311\site-packages\discord\app_commands\commands.py", line 853, in _invoke_with_namespace
    return await self._do_call(interaction, transformed_values)
           ^^^^^^^^^^^^^^^^^^^^^^^^^^^^^^^^^^^^^^^^^^^^^^^^^^^^
  File "C:\Users\WalkenNi\AppData\Local\Packages\PythonSoftwareFoundation.Python.3.11_qbz5n2kfra8p0\LocalCache\local-packages\Python311\site-packages\discord\app_commands\commands.py", line 842, in _do_call
    raise CommandInvokeError(self, e) from e
discord.app_commands.errors.CommandInvokeError: Command 'wb_search' raised an exception: TypeError: CustomLogger.log() missing 1 required positional argument: 'message'
2023-08-25 09:11:15 [INFO]: Successfully connected to: e:\Discord\BerechtiBotServer\database\wb_storing.db
2023-08-25 09:11:15 [WARNING]: Entry with ID: 5 was deleted.
2023-08-25 09:11:15 [ERROR]: Ignoring exception in command 'wb_delete'
Traceback (most recent call last):
  File "C:\Users\WalkenNi\AppData\Local\Packages\PythonSoftwareFoundation.Python.3.11_qbz5n2kfra8p0\LocalCache\local-packages\Python311\site-packages\discord\app_commands\commands.py", line 827, in _do_call
    return await self._callback(self.binding, interaction, **params)  # type: ignore
           ^^^^^^^^^^^^^^^^^^^^^^^^^^^^^^^^^^^^^^^^^^^^^^^^^^^^^^^^^
  File "e:\Discord\BerechtiBotServer\cogs\wb_delete.py", line 14, in WBDelete_command
    try:
  File "C:\Users\WalkenNi\AppData\Local\Packages\PythonSoftwareFoundation.Python.3.11_qbz5n2kfra8p0\LocalCache\local-packages\Python311\site-packages\discord\interactions.py", line 801, in send_message
    await adapter.create_interaction_response(
  File "C:\Users\WalkenNi\AppData\Local\Packages\PythonSoftwareFoundation.Python.3.11_qbz5n2kfra8p0\LocalCache\local-packages\Python311\site-packages\discord\webhook\async_.py", line 219, in request
    raise NotFound(response, data)
discord.errors.NotFound: 404 Not Found (error code: 10062): Unknown interaction

The above exception was the direct cause of the following exception:

Traceback (most recent call last):
  File "C:\Users\WalkenNi\AppData\Local\Packages\PythonSoftwareFoundation.Python.3.11_qbz5n2kfra8p0\LocalCache\local-packages\Python311\site-packages\discord\app_commands\tree.py", line 1248, in _call
    await command._invoke_with_namespace(interaction, namespace)
  File "C:\Users\WalkenNi\AppData\Local\Packages\PythonSoftwareFoundation.Python.3.11_qbz5n2kfra8p0\LocalCache\local-packages\Python311\site-packages\discord\app_commands\commands.py", line 853, in _invoke_with_namespace
    return await self._do_call(interaction, transformed_values)
           ^^^^^^^^^^^^^^^^^^^^^^^^^^^^^^^^^^^^^^^^^^^^^^^^^^^^
  File "C:\Users\WalkenNi\AppData\Local\Packages\PythonSoftwareFoundation.Python.3.11_qbz5n2kfra8p0\LocalCache\local-packages\Python311\site-packages\discord\app_commands\commands.py", line 846, in _do_call
    raise CommandInvokeError(self, e) from e
discord.app_commands.errors.CommandInvokeError: Command 'wb_delete' raised an exception: NotFound: 404 Not Found (error code: 10062): Unknown interaction
2023-08-25 09:11:27 [ERROR]: Ignoring exception in command 'wb_search'
Traceback (most recent call last):
  File "C:\Users\WalkenNi\AppData\Local\Packages\PythonSoftwareFoundation.Python.3.11_qbz5n2kfra8p0\LocalCache\local-packages\Python311\site-packages\discord\app_commands\commands.py", line 827, in _do_call
    return await self._callback(self.binding, interaction, **params)  # type: ignore
           ^^^^^^^^^^^^^^^^^^^^^^^^^^^^^^^^^^^^^^^^^^^^^^^^^^^^^^^^^
  File "e:\Discord\BerechtiBotServer\cogs\wb_search.py", line 16, in wbsearch_command
    try:
TypeError: CustomLogger.log() missing 1 required positional argument: 'message'

The above exception was the direct cause of the following exception:

Traceback (most recent call last):
  File "C:\Users\WalkenNi\AppData\Local\Packages\PythonSoftwareFoundation.Python.3.11_qbz5n2kfra8p0\LocalCache\local-packages\Python311\site-packages\discord\app_commands\tree.py", line 1248, in _call
    await command._invoke_with_namespace(interaction, namespace)
  File "C:\Users\WalkenNi\AppData\Local\Packages\PythonSoftwareFoundation.Python.3.11_qbz5n2kfra8p0\LocalCache\local-packages\Python311\site-packages\discord\app_commands\commands.py", line 853, in _invoke_with_namespace
    return await self._do_call(interaction, transformed_values)
           ^^^^^^^^^^^^^^^^^^^^^^^^^^^^^^^^^^^^^^^^^^^^^^^^^^^^
  File "C:\Users\WalkenNi\AppData\Local\Packages\PythonSoftwareFoundation.Python.3.11_qbz5n2kfra8p0\LocalCache\local-packages\Python311\site-packages\discord\app_commands\commands.py", line 842, in _do_call
    raise CommandInvokeError(self, e) from e
discord.app_commands.errors.CommandInvokeError: Command 'wb_search' raised an exception: TypeError: CustomLogger.log() missing 1 required positional argument: 'message'
2023-08-25 09:17:17 [ERROR]: Ignoring exception in command tree
Traceback (most recent call last):
  File "C:\Users\WalkenNi\AppData\Local\Packages\PythonSoftwareFoundation.Python.3.11_qbz5n2kfra8p0\LocalCache\local-packages\Python311\site-packages\discord\app_commands\tree.py", line 1089, in wrapper
    await self._call(interaction)
  File "C:\Users\WalkenNi\AppData\Local\Packages\PythonSoftwareFoundation.Python.3.11_qbz5n2kfra8p0\LocalCache\local-packages\Python311\site-packages\discord\app_commands\tree.py", line 1221, in _call
    command, options = self._get_app_command_options(data)
                       ^^^^^^^^^^^^^^^^^^^^^^^^^^^^^^^^^^^
  File "C:\Users\WalkenNi\AppData\Local\Packages\PythonSoftwareFoundation.Python.3.11_qbz5n2kfra8p0\LocalCache\local-packages\Python311\site-packages\discord\app_commands\tree.py", line 1125, in _get_app_command_options
    raise CommandNotFound(name, parents)
discord.app_commands.errors.CommandNotFound: Application command 'wb_new_entry' not found
2023-08-25 09:19:02 [ERROR]: Ignoring exception in command tree
Traceback (most recent call last):
  File "C:\Users\WalkenNi\AppData\Local\Packages\PythonSoftwareFoundation.Python.3.11_qbz5n2kfra8p0\LocalCache\local-packages\Python311\site-packages\discord\app_commands\tree.py", line 1089, in wrapper
    await self._call(interaction)
  File "C:\Users\WalkenNi\AppData\Local\Packages\PythonSoftwareFoundation.Python.3.11_qbz5n2kfra8p0\LocalCache\local-packages\Python311\site-packages\discord\app_commands\tree.py", line 1221, in _call
    command, options = self._get_app_command_options(data)
                       ^^^^^^^^^^^^^^^^^^^^^^^^^^^^^^^^^^^
  File "C:\Users\WalkenNi\AppData\Local\Packages\PythonSoftwareFoundation.Python.3.11_qbz5n2kfra8p0\LocalCache\local-packages\Python311\site-packages\discord\app_commands\tree.py", line 1125, in _get_app_command_options
    raise CommandNotFound(name, parents)
discord.app_commands.errors.CommandNotFound: Application command 'wb_new_entry' not found
2023-08-25 09:19:14 [INFO]: Successfully connected to: e:\Discord\BerechtiBotServer\database\wb_storing.db
2023-08-25 09:19:14 [ERROR]: An error occurred: time data 'asd' does not match format '%d%m%Y'
2023-08-25 09:19:18 [INFO]: Successfully connected to: e:\Discord\BerechtiBotServer\database\wb_storing.db
2023-08-25 09:19:18 [WARNING]: Entry with ID: 5 was deleted.
2023-08-25 09:20:06 [INFO]: Successfully connected to: e:\Discord\BerechtiBotServer\database\wb_storing.db
2023-08-25 09:20:06 [INFO]: A match was found
2023-08-25 09:20:06 [INFO]: A match was found
2023-08-25 09:20:07 [ERROR]: An error occurred: 404 Not Found (error code: 10062): Unknown interaction
2023-08-25 09:20:22 [ERROR]: Ignoring exception in command tree
Traceback (most recent call last):
  File "C:\Users\WalkenNi\AppData\Local\Packages\PythonSoftwareFoundation.Python.3.11_qbz5n2kfra8p0\LocalCache\local-packages\Python311\site-packages\discord\app_commands\tree.py", line 1089, in wrapper
    await self._call(interaction)
  File "C:\Users\WalkenNi\AppData\Local\Packages\PythonSoftwareFoundation.Python.3.11_qbz5n2kfra8p0\LocalCache\local-packages\Python311\site-packages\discord\app_commands\tree.py", line 1221, in _call
    command, options = self._get_app_command_options(data)
                       ^^^^^^^^^^^^^^^^^^^^^^^^^^^^^^^^^^^
  File "C:\Users\WalkenNi\AppData\Local\Packages\PythonSoftwareFoundation.Python.3.11_qbz5n2kfra8p0\LocalCache\local-packages\Python311\site-packages\discord\app_commands\tree.py", line 1125, in _get_app_command_options
    raise CommandNotFound(name, parents)
discord.app_commands.errors.CommandNotFound: Application command 'wb_new_entry' not found
2023-08-25 09:20:32 [INFO]: Successfully connected to: e:\Discord\BerechtiBotServer\database\wb_storing.db
2023-08-25 09:20:32 [ERROR]: An error occurred: time data 'asd' does not match format '%d%m%Y'
2023-08-25 09:20:49 [INFO]: Successfully connected to: e:\Discord\BerechtiBotServer\database\wb_storing.db
2023-08-25 09:20:49 [WARNING]: Entry with ID: 5 was deleted.
2023-08-25 09:21:19 [INFO]: Successfully connected to: e:\Discord\BerechtiBotServer\database\wb_storing.db
2023-08-25 09:21:19 [INFO]: A match was found
2023-08-25 09:21:20 [ERROR]: An error occurred: 400 Bad Request (error code: 40060): Interaction has already been acknowledged.
2023-08-25 09:22:56 [ERROR]: Ignoring exception in command tree
Traceback (most recent call last):
  File "C:\Users\WalkenNi\AppData\Local\Packages\PythonSoftwareFoundation.Python.3.11_qbz5n2kfra8p0\LocalCache\local-packages\Python311\site-packages\discord\app_commands\tree.py", line 1089, in wrapper
    await self._call(interaction)
  File "C:\Users\WalkenNi\AppData\Local\Packages\PythonSoftwareFoundation.Python.3.11_qbz5n2kfra8p0\LocalCache\local-packages\Python311\site-packages\discord\app_commands\tree.py", line 1221, in _call
    command, options = self._get_app_command_options(data)
                       ^^^^^^^^^^^^^^^^^^^^^^^^^^^^^^^^^^^
  File "C:\Users\WalkenNi\AppData\Local\Packages\PythonSoftwareFoundation.Python.3.11_qbz5n2kfra8p0\LocalCache\local-packages\Python311\site-packages\discord\app_commands\tree.py", line 1125, in _get_app_command_options
    raise CommandNotFound(name, parents)
discord.app_commands.errors.CommandNotFound: Application command 'wb_new_entry' not found
2023-08-25 09:23:09 [INFO]: Successfully connected to: e:\Discord\BerechtiBotServer\database\wb_storing.db
2023-08-25 09:23:09 [ERROR]: An error occurred: time data '48' does not match format '%d%m%Y'
2023-08-25 09:23:14 [INFO]: Successfully connected to: e:\Discord\BerechtiBotServer\database\wb_storing.db
2023-08-25 09:23:14 [WARNING]: Entry with ID: 5 was deleted.
2023-08-25 09:23:15 [ERROR]: Ignoring exception in command 'wb_delete'
Traceback (most recent call last):
  File "C:\Users\WalkenNi\AppData\Local\Packages\PythonSoftwareFoundation.Python.3.11_qbz5n2kfra8p0\LocalCache\local-packages\Python311\site-packages\discord\app_commands\commands.py", line 827, in _do_call
    return await self._callback(self.binding, interaction, **params)  # type: ignore
           ^^^^^^^^^^^^^^^^^^^^^^^^^^^^^^^^^^^^^^^^^^^^^^^^^^^^^^^^^
  File "e:\Discord\BerechtiBotServer\cogs\wb_delete.py", line 14, in WBDelete_command
    #try:
  File "C:\Users\WalkenNi\AppData\Local\Packages\PythonSoftwareFoundation.Python.3.11_qbz5n2kfra8p0\LocalCache\local-packages\Python311\site-packages\discord\interactions.py", line 801, in send_message
    await adapter.create_interaction_response(
  File "C:\Users\WalkenNi\AppData\Local\Packages\PythonSoftwareFoundation.Python.3.11_qbz5n2kfra8p0\LocalCache\local-packages\Python311\site-packages\discord\webhook\async_.py", line 219, in request
    raise NotFound(response, data)
discord.errors.NotFound: 404 Not Found (error code: 10062): Unknown interaction

The above exception was the direct cause of the following exception:

Traceback (most recent call last):
  File "C:\Users\WalkenNi\AppData\Local\Packages\PythonSoftwareFoundation.Python.3.11_qbz5n2kfra8p0\LocalCache\local-packages\Python311\site-packages\discord\app_commands\tree.py", line 1248, in _call
    await command._invoke_with_namespace(interaction, namespace)
  File "C:\Users\WalkenNi\AppData\Local\Packages\PythonSoftwareFoundation.Python.3.11_qbz5n2kfra8p0\LocalCache\local-packages\Python311\site-packages\discord\app_commands\commands.py", line 853, in _invoke_with_namespace
    return await self._do_call(interaction, transformed_values)
           ^^^^^^^^^^^^^^^^^^^^^^^^^^^^^^^^^^^^^^^^^^^^^^^^^^^^
  File "C:\Users\WalkenNi\AppData\Local\Packages\PythonSoftwareFoundation.Python.3.11_qbz5n2kfra8p0\LocalCache\local-packages\Python311\site-packages\discord\app_commands\commands.py", line 846, in _do_call
    raise CommandInvokeError(self, e) from e
discord.app_commands.errors.CommandInvokeError: Command 'wb_delete' raised an exception: NotFound: 404 Not Found (error code: 10062): Unknown interaction
2023-08-25 09:26:47 [ERROR]: Ignoring exception in command tree
Traceback (most recent call last):
  File "C:\Users\WalkenNi\AppData\Local\Packages\PythonSoftwareFoundation.Python.3.11_qbz5n2kfra8p0\LocalCache\local-packages\Python311\site-packages\discord\app_commands\tree.py", line 1089, in wrapper
    await self._call(interaction)
  File "C:\Users\WalkenNi\AppData\Local\Packages\PythonSoftwareFoundation.Python.3.11_qbz5n2kfra8p0\LocalCache\local-packages\Python311\site-packages\discord\app_commands\tree.py", line 1221, in _call
    command, options = self._get_app_command_options(data)
                       ^^^^^^^^^^^^^^^^^^^^^^^^^^^^^^^^^^^
  File "C:\Users\WalkenNi\AppData\Local\Packages\PythonSoftwareFoundation.Python.3.11_qbz5n2kfra8p0\LocalCache\local-packages\Python311\site-packages\discord\app_commands\tree.py", line 1125, in _get_app_command_options
    raise CommandNotFound(name, parents)
discord.app_commands.errors.CommandNotFound: Application command 'wb_create_doc' not found
2023-08-25 09:43:27 [ERROR]: Ignoring exception in command tree
Traceback (most recent call last):
  File "C:\Users\WalkenNi\AppData\Local\Packages\PythonSoftwareFoundation.Python.3.11_qbz5n2kfra8p0\LocalCache\local-packages\Python311\site-packages\discord\app_commands\tree.py", line 1089, in wrapper
    await self._call(interaction)
  File "C:\Users\WalkenNi\AppData\Local\Packages\PythonSoftwareFoundation.Python.3.11_qbz5n2kfra8p0\LocalCache\local-packages\Python311\site-packages\discord\app_commands\tree.py", line 1221, in _call
    command, options = self._get_app_command_options(data)
                       ^^^^^^^^^^^^^^^^^^^^^^^^^^^^^^^^^^^
  File "C:\Users\WalkenNi\AppData\Local\Packages\PythonSoftwareFoundation.Python.3.11_qbz5n2kfra8p0\LocalCache\local-packages\Python311\site-packages\discord\app_commands\tree.py", line 1125, in _get_app_command_options
    raise CommandNotFound(name, parents)
discord.app_commands.errors.CommandNotFound: Application command 'wb_create_doc' not found
2023-08-25 09:45:31 [ERROR]: Ignoring exception in command tree
Traceback (most recent call last):
  File "C:\Users\WalkenNi\AppData\Local\Packages\PythonSoftwareFoundation.Python.3.11_qbz5n2kfra8p0\LocalCache\local-packages\Python311\site-packages\discord\app_commands\tree.py", line 1089, in wrapper
    await self._call(interaction)
  File "C:\Users\WalkenNi\AppData\Local\Packages\PythonSoftwareFoundation.Python.3.11_qbz5n2kfra8p0\LocalCache\local-packages\Python311\site-packages\discord\app_commands\tree.py", line 1221, in _call
    command, options = self._get_app_command_options(data)
                       ^^^^^^^^^^^^^^^^^^^^^^^^^^^^^^^^^^^
  File "C:\Users\WalkenNi\AppData\Local\Packages\PythonSoftwareFoundation.Python.3.11_qbz5n2kfra8p0\LocalCache\local-packages\Python311\site-packages\discord\app_commands\tree.py", line 1125, in _get_app_command_options
    raise CommandNotFound(name, parents)
discord.app_commands.errors.CommandNotFound: Application command 'wb_create_doc' not found
2023-08-25 09:47:53 [ERROR]: Ignoring exception in command tree
Traceback (most recent call last):
  File "C:\Users\WalkenNi\AppData\Local\Packages\PythonSoftwareFoundation.Python.3.11_qbz5n2kfra8p0\LocalCache\local-packages\Python311\site-packages\discord\app_commands\tree.py", line 1089, in wrapper
    await self._call(interaction)
  File "C:\Users\WalkenNi\AppData\Local\Packages\PythonSoftwareFoundation.Python.3.11_qbz5n2kfra8p0\LocalCache\local-packages\Python311\site-packages\discord\app_commands\tree.py", line 1221, in _call
    command, options = self._get_app_command_options(data)
                       ^^^^^^^^^^^^^^^^^^^^^^^^^^^^^^^^^^^
  File "C:\Users\WalkenNi\AppData\Local\Packages\PythonSoftwareFoundation.Python.3.11_qbz5n2kfra8p0\LocalCache\local-packages\Python311\site-packages\discord\app_commands\tree.py", line 1125, in _get_app_command_options
    raise CommandNotFound(name, parents)
discord.app_commands.errors.CommandNotFound: Application command 'wb_create_doc' not found
2023-08-25 09:49:35 [ERROR]: Ignoring exception in command tree
Traceback (most recent call last):
  File "C:\Users\WalkenNi\AppData\Local\Packages\PythonSoftwareFoundation.Python.3.11_qbz5n2kfra8p0\LocalCache\local-packages\Python311\site-packages\discord\app_commands\tree.py", line 1089, in wrapper
    await self._call(interaction)
  File "C:\Users\WalkenNi\AppData\Local\Packages\PythonSoftwareFoundation.Python.3.11_qbz5n2kfra8p0\LocalCache\local-packages\Python311\site-packages\discord\app_commands\tree.py", line 1221, in _call
    command, options = self._get_app_command_options(data)
                       ^^^^^^^^^^^^^^^^^^^^^^^^^^^^^^^^^^^
  File "C:\Users\WalkenNi\AppData\Local\Packages\PythonSoftwareFoundation.Python.3.11_qbz5n2kfra8p0\LocalCache\local-packages\Python311\site-packages\discord\app_commands\tree.py", line 1125, in _get_app_command_options
    raise CommandNotFound(name, parents)
discord.app_commands.errors.CommandNotFound: Application command 'wb_create_doc' not found
2023-08-25 09:51:37 [ERROR]: Ignoring exception in command tree
Traceback (most recent call last):
  File "C:\Users\WalkenNi\AppData\Local\Packages\PythonSoftwareFoundation.Python.3.11_qbz5n2kfra8p0\LocalCache\local-packages\Python311\site-packages\discord\app_commands\tree.py", line 1089, in wrapper
    await self._call(interaction)
  File "C:\Users\WalkenNi\AppData\Local\Packages\PythonSoftwareFoundation.Python.3.11_qbz5n2kfra8p0\LocalCache\local-packages\Python311\site-packages\discord\app_commands\tree.py", line 1221, in _call
    command, options = self._get_app_command_options(data)
                       ^^^^^^^^^^^^^^^^^^^^^^^^^^^^^^^^^^^
  File "C:\Users\WalkenNi\AppData\Local\Packages\PythonSoftwareFoundation.Python.3.11_qbz5n2kfra8p0\LocalCache\local-packages\Python311\site-packages\discord\app_commands\tree.py", line 1125, in _get_app_command_options
    raise CommandNotFound(name, parents)
discord.app_commands.errors.CommandNotFound: Application command 'wb_create_doc' not found
2023-08-25 09:53:18 [ERROR]: Ignoring exception in command tree
Traceback (most recent call last):
  File "C:\Users\WalkenNi\AppData\Local\Packages\PythonSoftwareFoundation.Python.3.11_qbz5n2kfra8p0\LocalCache\local-packages\Python311\site-packages\discord\app_commands\tree.py", line 1089, in wrapper
    await self._call(interaction)
  File "C:\Users\WalkenNi\AppData\Local\Packages\PythonSoftwareFoundation.Python.3.11_qbz5n2kfra8p0\LocalCache\local-packages\Python311\site-packages\discord\app_commands\tree.py", line 1221, in _call
    command, options = self._get_app_command_options(data)
                       ^^^^^^^^^^^^^^^^^^^^^^^^^^^^^^^^^^^
  File "C:\Users\WalkenNi\AppData\Local\Packages\PythonSoftwareFoundation.Python.3.11_qbz5n2kfra8p0\LocalCache\local-packages\Python311\site-packages\discord\app_commands\tree.py", line 1125, in _get_app_command_options
    raise CommandNotFound(name, parents)
discord.app_commands.errors.CommandNotFound: Application command 'wb_create_doc' not found
2023-08-25 09:54:38 [ERROR]: Ignoring exception in command tree
Traceback (most recent call last):
  File "C:\Users\WalkenNi\AppData\Local\Packages\PythonSoftwareFoundation.Python.3.11_qbz5n2kfra8p0\LocalCache\local-packages\Python311\site-packages\discord\app_commands\tree.py", line 1089, in wrapper
    await self._call(interaction)
  File "C:\Users\WalkenNi\AppData\Local\Packages\PythonSoftwareFoundation.Python.3.11_qbz5n2kfra8p0\LocalCache\local-packages\Python311\site-packages\discord\app_commands\tree.py", line 1221, in _call
    command, options = self._get_app_command_options(data)
                       ^^^^^^^^^^^^^^^^^^^^^^^^^^^^^^^^^^^
  File "C:\Users\WalkenNi\AppData\Local\Packages\PythonSoftwareFoundation.Python.3.11_qbz5n2kfra8p0\LocalCache\local-packages\Python311\site-packages\discord\app_commands\tree.py", line 1125, in _get_app_command_options
    raise CommandNotFound(name, parents)
discord.app_commands.errors.CommandNotFound: Application command 'wb_create_doc' not found
2023-08-25 09:56:46 [ERROR]: Ignoring exception in command tree
Traceback (most recent call last):
  File "C:\Users\WalkenNi\AppData\Local\Packages\PythonSoftwareFoundation.Python.3.11_qbz5n2kfra8p0\LocalCache\local-packages\Python311\site-packages\discord\app_commands\tree.py", line 1089, in wrapper
    await self._call(interaction)
  File "C:\Users\WalkenNi\AppData\Local\Packages\PythonSoftwareFoundation.Python.3.11_qbz5n2kfra8p0\LocalCache\local-packages\Python311\site-packages\discord\app_commands\tree.py", line 1221, in _call
    command, options = self._get_app_command_options(data)
                       ^^^^^^^^^^^^^^^^^^^^^^^^^^^^^^^^^^^
  File "C:\Users\WalkenNi\AppData\Local\Packages\PythonSoftwareFoundation.Python.3.11_qbz5n2kfra8p0\LocalCache\local-packages\Python311\site-packages\discord\app_commands\tree.py", line 1125, in _get_app_command_options
    raise CommandNotFound(name, parents)
discord.app_commands.errors.CommandNotFound: Application command 'wb_create_doc' not found
2023-08-25 09:57:25 [ERROR]: Ignoring exception in command tree
Traceback (most recent call last):
  File "C:\Users\WalkenNi\AppData\Local\Packages\PythonSoftwareFoundation.Python.3.11_qbz5n2kfra8p0\LocalCache\local-packages\Python311\site-packages\discord\app_commands\tree.py", line 1089, in wrapper
    await self._call(interaction)
  File "C:\Users\WalkenNi\AppData\Local\Packages\PythonSoftwareFoundation.Python.3.11_qbz5n2kfra8p0\LocalCache\local-packages\Python311\site-packages\discord\app_commands\tree.py", line 1221, in _call
    command, options = self._get_app_command_options(data)
                       ^^^^^^^^^^^^^^^^^^^^^^^^^^^^^^^^^^^
  File "C:\Users\WalkenNi\AppData\Local\Packages\PythonSoftwareFoundation.Python.3.11_qbz5n2kfra8p0\LocalCache\local-packages\Python311\site-packages\discord\app_commands\tree.py", line 1125, in _get_app_command_options
    raise CommandNotFound(name, parents)
discord.app_commands.errors.CommandNotFound: Application command 'wb_create_doc' not found
2023-08-25 09:59:39 [ERROR]: Ignoring exception in command tree
Traceback (most recent call last):
  File "C:\Users\WalkenNi\AppData\Local\Packages\PythonSoftwareFoundation.Python.3.11_qbz5n2kfra8p0\LocalCache\local-packages\Python311\site-packages\discord\app_commands\tree.py", line 1089, in wrapper
    await self._call(interaction)
  File "C:\Users\WalkenNi\AppData\Local\Packages\PythonSoftwareFoundation.Python.3.11_qbz5n2kfra8p0\LocalCache\local-packages\Python311\site-packages\discord\app_commands\tree.py", line 1221, in _call
    command, options = self._get_app_command_options(data)
                       ^^^^^^^^^^^^^^^^^^^^^^^^^^^^^^^^^^^
  File "C:\Users\WalkenNi\AppData\Local\Packages\PythonSoftwareFoundation.Python.3.11_qbz5n2kfra8p0\LocalCache\local-packages\Python311\site-packages\discord\app_commands\tree.py", line 1125, in _get_app_command_options
    raise CommandNotFound(name, parents)
discord.app_commands.errors.CommandNotFound: Application command 'wb_create_doc' not found
2023-08-25 10:00:48 [ERROR]: Ignoring exception in command tree
Traceback (most recent call last):
  File "C:\Users\WalkenNi\AppData\Local\Packages\PythonSoftwareFoundation.Python.3.11_qbz5n2kfra8p0\LocalCache\local-packages\Python311\site-packages\discord\app_commands\tree.py", line 1089, in wrapper
    await self._call(interaction)
  File "C:\Users\WalkenNi\AppData\Local\Packages\PythonSoftwareFoundation.Python.3.11_qbz5n2kfra8p0\LocalCache\local-packages\Python311\site-packages\discord\app_commands\tree.py", line 1221, in _call
    command, options = self._get_app_command_options(data)
                       ^^^^^^^^^^^^^^^^^^^^^^^^^^^^^^^^^^^
  File "C:\Users\WalkenNi\AppData\Local\Packages\PythonSoftwareFoundation.Python.3.11_qbz5n2kfra8p0\LocalCache\local-packages\Python311\site-packages\discord\app_commands\tree.py", line 1125, in _get_app_command_options
    raise CommandNotFound(name, parents)
discord.app_commands.errors.CommandNotFound: Application command 'wb_create_doc' not found
2023-08-25 10:01:18 [ERROR]: Ignoring exception in command tree
Traceback (most recent call last):
  File "C:\Users\WalkenNi\AppData\Local\Packages\PythonSoftwareFoundation.Python.3.11_qbz5n2kfra8p0\LocalCache\local-packages\Python311\site-packages\discord\app_commands\tree.py", line 1089, in wrapper
    await self._call(interaction)
  File "C:\Users\WalkenNi\AppData\Local\Packages\PythonSoftwareFoundation.Python.3.11_qbz5n2kfra8p0\LocalCache\local-packages\Python311\site-packages\discord\app_commands\tree.py", line 1221, in _call
    command, options = self._get_app_command_options(data)
                       ^^^^^^^^^^^^^^^^^^^^^^^^^^^^^^^^^^^
  File "C:\Users\WalkenNi\AppData\Local\Packages\PythonSoftwareFoundation.Python.3.11_qbz5n2kfra8p0\LocalCache\local-packages\Python311\site-packages\discord\app_commands\tree.py", line 1125, in _get_app_command_options
    raise CommandNotFound(name, parents)
discord.app_commands.errors.CommandNotFound: Application command 'wb_create_doc' not found
2023-08-25 10:02:49 [ERROR]: Ignoring exception in command tree
Traceback (most recent call last):
  File "C:\Users\WalkenNi\AppData\Local\Packages\PythonSoftwareFoundation.Python.3.11_qbz5n2kfra8p0\LocalCache\local-packages\Python311\site-packages\discord\app_commands\tree.py", line 1089, in wrapper
    await self._call(interaction)
  File "C:\Users\WalkenNi\AppData\Local\Packages\PythonSoftwareFoundation.Python.3.11_qbz5n2kfra8p0\LocalCache\local-packages\Python311\site-packages\discord\app_commands\tree.py", line 1221, in _call
    command, options = self._get_app_command_options(data)
                       ^^^^^^^^^^^^^^^^^^^^^^^^^^^^^^^^^^^
  File "C:\Users\WalkenNi\AppData\Local\Packages\PythonSoftwareFoundation.Python.3.11_qbz5n2kfra8p0\LocalCache\local-packages\Python311\site-packages\discord\app_commands\tree.py", line 1125, in _get_app_command_options
    raise CommandNotFound(name, parents)
discord.app_commands.errors.CommandNotFound: Application command 'wb_create_doc' not found
2023-08-25 10:03:44 [ERROR]: Ignoring exception in command tree
Traceback (most recent call last):
  File "C:\Users\WalkenNi\AppData\Local\Packages\PythonSoftwareFoundation.Python.3.11_qbz5n2kfra8p0\LocalCache\local-packages\Python311\site-packages\discord\app_commands\tree.py", line 1089, in wrapper
    await self._call(interaction)
  File "C:\Users\WalkenNi\AppData\Local\Packages\PythonSoftwareFoundation.Python.3.11_qbz5n2kfra8p0\LocalCache\local-packages\Python311\site-packages\discord\app_commands\tree.py", line 1221, in _call
    command, options = self._get_app_command_options(data)
                       ^^^^^^^^^^^^^^^^^^^^^^^^^^^^^^^^^^^
  File "C:\Users\WalkenNi\AppData\Local\Packages\PythonSoftwareFoundation.Python.3.11_qbz5n2kfra8p0\LocalCache\local-packages\Python311\site-packages\discord\app_commands\tree.py", line 1125, in _get_app_command_options
    raise CommandNotFound(name, parents)
discord.app_commands.errors.CommandNotFound: Application command 'wb_create_doc' not found
2023-08-25 10:04:34 [ERROR]: Ignoring exception in command tree
Traceback (most recent call last):
  File "C:\Users\WalkenNi\AppData\Local\Packages\PythonSoftwareFoundation.Python.3.11_qbz5n2kfra8p0\LocalCache\local-packages\Python311\site-packages\discord\app_commands\tree.py", line 1089, in wrapper
    await self._call(interaction)
  File "C:\Users\WalkenNi\AppData\Local\Packages\PythonSoftwareFoundation.Python.3.11_qbz5n2kfra8p0\LocalCache\local-packages\Python311\site-packages\discord\app_commands\tree.py", line 1221, in _call
    command, options = self._get_app_command_options(data)
                       ^^^^^^^^^^^^^^^^^^^^^^^^^^^^^^^^^^^
  File "C:\Users\WalkenNi\AppData\Local\Packages\PythonSoftwareFoundation.Python.3.11_qbz5n2kfra8p0\LocalCache\local-packages\Python311\site-packages\discord\app_commands\tree.py", line 1125, in _get_app_command_options
    raise CommandNotFound(name, parents)
discord.app_commands.errors.CommandNotFound: Application command 'wb_create_doc' not found
2023-08-25 10:06:13 [ERROR]: Ignoring exception in command tree
Traceback (most recent call last):
  File "C:\Users\WalkenNi\AppData\Local\Packages\PythonSoftwareFoundation.Python.3.11_qbz5n2kfra8p0\LocalCache\local-packages\Python311\site-packages\discord\app_commands\tree.py", line 1089, in wrapper
    await self._call(interaction)
  File "C:\Users\WalkenNi\AppData\Local\Packages\PythonSoftwareFoundation.Python.3.11_qbz5n2kfra8p0\LocalCache\local-packages\Python311\site-packages\discord\app_commands\tree.py", line 1221, in _call
    command, options = self._get_app_command_options(data)
                       ^^^^^^^^^^^^^^^^^^^^^^^^^^^^^^^^^^^
  File "C:\Users\WalkenNi\AppData\Local\Packages\PythonSoftwareFoundation.Python.3.11_qbz5n2kfra8p0\LocalCache\local-packages\Python311\site-packages\discord\app_commands\tree.py", line 1125, in _get_app_command_options
    raise CommandNotFound(name, parents)
discord.app_commands.errors.CommandNotFound: Application command 'wb_create_doc' not found
2023-08-25 10:06:54 [ERROR]: Ignoring exception in command tree
Traceback (most recent call last):
  File "C:\Users\WalkenNi\AppData\Local\Packages\PythonSoftwareFoundation.Python.3.11_qbz5n2kfra8p0\LocalCache\local-packages\Python311\site-packages\discord\app_commands\tree.py", line 1089, in wrapper
    await self._call(interaction)
  File "C:\Users\WalkenNi\AppData\Local\Packages\PythonSoftwareFoundation.Python.3.11_qbz5n2kfra8p0\LocalCache\local-packages\Python311\site-packages\discord\app_commands\tree.py", line 1221, in _call
    command, options = self._get_app_command_options(data)
                       ^^^^^^^^^^^^^^^^^^^^^^^^^^^^^^^^^^^
  File "C:\Users\WalkenNi\AppData\Local\Packages\PythonSoftwareFoundation.Python.3.11_qbz5n2kfra8p0\LocalCache\local-packages\Python311\site-packages\discord\app_commands\tree.py", line 1125, in _get_app_command_options
    raise CommandNotFound(name, parents)
discord.app_commands.errors.CommandNotFound: Application command 'wb_create_doc' not found
2023-08-25 10:07:23 [ERROR]: Ignoring exception in command tree
Traceback (most recent call last):
  File "C:\Users\WalkenNi\AppData\Local\Packages\PythonSoftwareFoundation.Python.3.11_qbz5n2kfra8p0\LocalCache\local-packages\Python311\site-packages\discord\app_commands\tree.py", line 1089, in wrapper
    await self._call(interaction)
  File "C:\Users\WalkenNi\AppData\Local\Packages\PythonSoftwareFoundation.Python.3.11_qbz5n2kfra8p0\LocalCache\local-packages\Python311\site-packages\discord\app_commands\tree.py", line 1221, in _call
    command, options = self._get_app_command_options(data)
                       ^^^^^^^^^^^^^^^^^^^^^^^^^^^^^^^^^^^
  File "C:\Users\WalkenNi\AppData\Local\Packages\PythonSoftwareFoundation.Python.3.11_qbz5n2kfra8p0\LocalCache\local-packages\Python311\site-packages\discord\app_commands\tree.py", line 1125, in _get_app_command_options
    raise CommandNotFound(name, parents)
discord.app_commands.errors.CommandNotFound: Application command 'wb_create_doc' not found
2023-08-25 10:07:46 [ERROR]: Ignoring exception in command tree
Traceback (most recent call last):
  File "C:\Users\WalkenNi\AppData\Local\Packages\PythonSoftwareFoundation.Python.3.11_qbz5n2kfra8p0\LocalCache\local-packages\Python311\site-packages\discord\app_commands\tree.py", line 1089, in wrapper
    await self._call(interaction)
  File "C:\Users\WalkenNi\AppData\Local\Packages\PythonSoftwareFoundation.Python.3.11_qbz5n2kfra8p0\LocalCache\local-packages\Python311\site-packages\discord\app_commands\tree.py", line 1221, in _call
    command, options = self._get_app_command_options(data)
                       ^^^^^^^^^^^^^^^^^^^^^^^^^^^^^^^^^^^
  File "C:\Users\WalkenNi\AppData\Local\Packages\PythonSoftwareFoundation.Python.3.11_qbz5n2kfra8p0\LocalCache\local-packages\Python311\site-packages\discord\app_commands\tree.py", line 1125, in _get_app_command_options
    raise CommandNotFound(name, parents)
discord.app_commands.errors.CommandNotFound: Application command 'wb_create_doc' not found
2023-08-25 10:08:05 [ERROR]: Ignoring exception in command tree
Traceback (most recent call last):
  File "C:\Users\WalkenNi\AppData\Local\Packages\PythonSoftwareFoundation.Python.3.11_qbz5n2kfra8p0\LocalCache\local-packages\Python311\site-packages\discord\app_commands\tree.py", line 1089, in wrapper
    await self._call(interaction)
  File "C:\Users\WalkenNi\AppData\Local\Packages\PythonSoftwareFoundation.Python.3.11_qbz5n2kfra8p0\LocalCache\local-packages\Python311\site-packages\discord\app_commands\tree.py", line 1221, in _call
    command, options = self._get_app_command_options(data)
                       ^^^^^^^^^^^^^^^^^^^^^^^^^^^^^^^^^^^
  File "C:\Users\WalkenNi\AppData\Local\Packages\PythonSoftwareFoundation.Python.3.11_qbz5n2kfra8p0\LocalCache\local-packages\Python311\site-packages\discord\app_commands\tree.py", line 1125, in _get_app_command_options
    raise CommandNotFound(name, parents)
discord.app_commands.errors.CommandNotFound: Application command 'wb_create_doc' not found
2023-08-25 10:12:28 [INFO]: Shard ID None has successfully RESUMED session 40c0457069e5a12b67ac0afa3b4e74d9.
2023-08-25 10:23:23 [ERROR]: Ignoring exception in command tree
Traceback (most recent call last):
  File "C:\Users\WalkenNi\AppData\Local\Packages\PythonSoftwareFoundation.Python.3.11_qbz5n2kfra8p0\LocalCache\local-packages\Python311\site-packages\discord\app_commands\tree.py", line 1089, in wrapper
    await self._call(interaction)
  File "C:\Users\WalkenNi\AppData\Local\Packages\PythonSoftwareFoundation.Python.3.11_qbz5n2kfra8p0\LocalCache\local-packages\Python311\site-packages\discord\app_commands\tree.py", line 1221, in _call
    command, options = self._get_app_command_options(data)
                       ^^^^^^^^^^^^^^^^^^^^^^^^^^^^^^^^^^^
  File "C:\Users\WalkenNi\AppData\Local\Packages\PythonSoftwareFoundation.Python.3.11_qbz5n2kfra8p0\LocalCache\local-packages\Python311\site-packages\discord\app_commands\tree.py", line 1125, in _get_app_command_options
    raise CommandNotFound(name, parents)
discord.app_commands.errors.CommandNotFound: Application command 'wb_create_doc' not found
2023-08-25 10:24:02 [ERROR]: Ignoring exception in command tree
Traceback (most recent call last):
  File "C:\Users\WalkenNi\AppData\Local\Packages\PythonSoftwareFoundation.Python.3.11_qbz5n2kfra8p0\LocalCache\local-packages\Python311\site-packages\discord\app_commands\tree.py", line 1089, in wrapper
    await self._call(interaction)
  File "C:\Users\WalkenNi\AppData\Local\Packages\PythonSoftwareFoundation.Python.3.11_qbz5n2kfra8p0\LocalCache\local-packages\Python311\site-packages\discord\app_commands\tree.py", line 1221, in _call
    command, options = self._get_app_command_options(data)
                       ^^^^^^^^^^^^^^^^^^^^^^^^^^^^^^^^^^^
  File "C:\Users\WalkenNi\AppData\Local\Packages\PythonSoftwareFoundation.Python.3.11_qbz5n2kfra8p0\LocalCache\local-packages\Python311\site-packages\discord\app_commands\tree.py", line 1125, in _get_app_command_options
    raise CommandNotFound(name, parents)
discord.app_commands.errors.CommandNotFound: Application command 'wb_create_doc' not found
2023-08-25 10:25:47 [ERROR]: Ignoring exception in command tree
Traceback (most recent call last):
  File "C:\Users\WalkenNi\AppData\Local\Packages\PythonSoftwareFoundation.Python.3.11_qbz5n2kfra8p0\LocalCache\local-packages\Python311\site-packages\discord\app_commands\tree.py", line 1089, in wrapper
    await self._call(interaction)
  File "C:\Users\WalkenNi\AppData\Local\Packages\PythonSoftwareFoundation.Python.3.11_qbz5n2kfra8p0\LocalCache\local-packages\Python311\site-packages\discord\app_commands\tree.py", line 1221, in _call
    command, options = self._get_app_command_options(data)
                       ^^^^^^^^^^^^^^^^^^^^^^^^^^^^^^^^^^^
  File "C:\Users\WalkenNi\AppData\Local\Packages\PythonSoftwareFoundation.Python.3.11_qbz5n2kfra8p0\LocalCache\local-packages\Python311\site-packages\discord\app_commands\tree.py", line 1125, in _get_app_command_options
    raise CommandNotFound(name, parents)
discord.app_commands.errors.CommandNotFound: Application command 'wb_create_doc' not found
2023-08-25 10:26:11 [ERROR]: Ignoring exception in command tree
Traceback (most recent call last):
  File "C:\Users\WalkenNi\AppData\Local\Packages\PythonSoftwareFoundation.Python.3.11_qbz5n2kfra8p0\LocalCache\local-packages\Python311\site-packages\discord\app_commands\tree.py", line 1089, in wrapper
    await self._call(interaction)
  File "C:\Users\WalkenNi\AppData\Local\Packages\PythonSoftwareFoundation.Python.3.11_qbz5n2kfra8p0\LocalCache\local-packages\Python311\site-packages\discord\app_commands\tree.py", line 1221, in _call
    command, options = self._get_app_command_options(data)
                       ^^^^^^^^^^^^^^^^^^^^^^^^^^^^^^^^^^^
  File "C:\Users\WalkenNi\AppData\Local\Packages\PythonSoftwareFoundation.Python.3.11_qbz5n2kfra8p0\LocalCache\local-packages\Python311\site-packages\discord\app_commands\tree.py", line 1125, in _get_app_command_options
    raise CommandNotFound(name, parents)
discord.app_commands.errors.CommandNotFound: Application command 'wb_create_doc' not found
2023-08-25 10:26:40 [ERROR]: Ignoring exception in command tree
Traceback (most recent call last):
  File "C:\Users\WalkenNi\AppData\Local\Packages\PythonSoftwareFoundation.Python.3.11_qbz5n2kfra8p0\LocalCache\local-packages\Python311\site-packages\discord\app_commands\tree.py", line 1089, in wrapper
    await self._call(interaction)
  File "C:\Users\WalkenNi\AppData\Local\Packages\PythonSoftwareFoundation.Python.3.11_qbz5n2kfra8p0\LocalCache\local-packages\Python311\site-packages\discord\app_commands\tree.py", line 1221, in _call
    command, options = self._get_app_command_options(data)
                       ^^^^^^^^^^^^^^^^^^^^^^^^^^^^^^^^^^^
  File "C:\Users\WalkenNi\AppData\Local\Packages\PythonSoftwareFoundation.Python.3.11_qbz5n2kfra8p0\LocalCache\local-packages\Python311\site-packages\discord\app_commands\tree.py", line 1125, in _get_app_command_options
    raise CommandNotFound(name, parents)
discord.app_commands.errors.CommandNotFound: Application command 'wb_create_doc' not found
2023-08-25 10:31:54 [ERROR]: Ignoring exception in command tree
Traceback (most recent call last):
  File "C:\Users\WalkenNi\AppData\Local\Packages\PythonSoftwareFoundation.Python.3.11_qbz5n2kfra8p0\LocalCache\local-packages\Python311\site-packages\discord\app_commands\tree.py", line 1089, in wrapper
    await self._call(interaction)
  File "C:\Users\WalkenNi\AppData\Local\Packages\PythonSoftwareFoundation.Python.3.11_qbz5n2kfra8p0\LocalCache\local-packages\Python311\site-packages\discord\app_commands\tree.py", line 1221, in _call
    command, options = self._get_app_command_options(data)
                       ^^^^^^^^^^^^^^^^^^^^^^^^^^^^^^^^^^^
  File "C:\Users\WalkenNi\AppData\Local\Packages\PythonSoftwareFoundation.Python.3.11_qbz5n2kfra8p0\LocalCache\local-packages\Python311\site-packages\discord\app_commands\tree.py", line 1125, in _get_app_command_options
    raise CommandNotFound(name, parents)
discord.app_commands.errors.CommandNotFound: Application command 'wb_create_doc' not found
2023-08-25 10:31:59 [ERROR]: Ignoring exception in command tree
Traceback (most recent call last):
  File "C:\Users\WalkenNi\AppData\Local\Packages\PythonSoftwareFoundation.Python.3.11_qbz5n2kfra8p0\LocalCache\local-packages\Python311\site-packages\discord\app_commands\tree.py", line 1089, in wrapper
    await self._call(interaction)
  File "C:\Users\WalkenNi\AppData\Local\Packages\PythonSoftwareFoundation.Python.3.11_qbz5n2kfra8p0\LocalCache\local-packages\Python311\site-packages\discord\app_commands\tree.py", line 1221, in _call
    command, options = self._get_app_command_options(data)
                       ^^^^^^^^^^^^^^^^^^^^^^^^^^^^^^^^^^^
  File "C:\Users\WalkenNi\AppData\Local\Packages\PythonSoftwareFoundation.Python.3.11_qbz5n2kfra8p0\LocalCache\local-packages\Python311\site-packages\discord\app_commands\tree.py", line 1125, in _get_app_command_options
    raise CommandNotFound(name, parents)
discord.app_commands.errors.CommandNotFound: Application command 'wb_create_doc' not found
2023-08-25 10:32:20 [ERROR]: Ignoring exception in command tree
Traceback (most recent call last):
  File "C:\Users\WalkenNi\AppData\Local\Packages\PythonSoftwareFoundation.Python.3.11_qbz5n2kfra8p0\LocalCache\local-packages\Python311\site-packages\discord\app_commands\tree.py", line 1089, in wrapper
    await self._call(interaction)
  File "C:\Users\WalkenNi\AppData\Local\Packages\PythonSoftwareFoundation.Python.3.11_qbz5n2kfra8p0\LocalCache\local-packages\Python311\site-packages\discord\app_commands\tree.py", line 1221, in _call
    command, options = self._get_app_command_options(data)
                       ^^^^^^^^^^^^^^^^^^^^^^^^^^^^^^^^^^^
  File "C:\Users\WalkenNi\AppData\Local\Packages\PythonSoftwareFoundation.Python.3.11_qbz5n2kfra8p0\LocalCache\local-packages\Python311\site-packages\discord\app_commands\tree.py", line 1125, in _get_app_command_options
    raise CommandNotFound(name, parents)
discord.app_commands.errors.CommandNotFound: Application command 'wb_create_doc' not found
2023-08-25 10:33:39 [ERROR]: Ignoring exception in command tree
Traceback (most recent call last):
  File "C:\Users\WalkenNi\AppData\Local\Packages\PythonSoftwareFoundation.Python.3.11_qbz5n2kfra8p0\LocalCache\local-packages\Python311\site-packages\discord\app_commands\tree.py", line 1089, in wrapper
    await self._call(interaction)
  File "C:\Users\WalkenNi\AppData\Local\Packages\PythonSoftwareFoundation.Python.3.11_qbz5n2kfra8p0\LocalCache\local-packages\Python311\site-packages\discord\app_commands\tree.py", line 1221, in _call
    command, options = self._get_app_command_options(data)
                       ^^^^^^^^^^^^^^^^^^^^^^^^^^^^^^^^^^^
  File "C:\Users\WalkenNi\AppData\Local\Packages\PythonSoftwareFoundation.Python.3.11_qbz5n2kfra8p0\LocalCache\local-packages\Python311\site-packages\discord\app_commands\tree.py", line 1125, in _get_app_command_options
    raise CommandNotFound(name, parents)
discord.app_commands.errors.CommandNotFound: Application command 'wb_create_doc' not found
2023-08-25 10:39:44 [ERROR]: Ignoring exception in command tree
Traceback (most recent call last):
  File "C:\Users\WalkenNi\AppData\Local\Packages\PythonSoftwareFoundation.Python.3.11_qbz5n2kfra8p0\LocalCache\local-packages\Python311\site-packages\discord\app_commands\tree.py", line 1089, in wrapper
    await self._call(interaction)
  File "C:\Users\WalkenNi\AppData\Local\Packages\PythonSoftwareFoundation.Python.3.11_qbz5n2kfra8p0\LocalCache\local-packages\Python311\site-packages\discord\app_commands\tree.py", line 1221, in _call
    command, options = self._get_app_command_options(data)
                       ^^^^^^^^^^^^^^^^^^^^^^^^^^^^^^^^^^^
  File "C:\Users\WalkenNi\AppData\Local\Packages\PythonSoftwareFoundation.Python.3.11_qbz5n2kfra8p0\LocalCache\local-packages\Python311\site-packages\discord\app_commands\tree.py", line 1125, in _get_app_command_options
    raise CommandNotFound(name, parents)
discord.app_commands.errors.CommandNotFound: Application command 'wb_create_doc' not found
2023-08-25 10:41:54 [ERROR]: Ignoring exception in command tree
Traceback (most recent call last):
  File "C:\Users\WalkenNi\AppData\Local\Packages\PythonSoftwareFoundation.Python.3.11_qbz5n2kfra8p0\LocalCache\local-packages\Python311\site-packages\discord\app_commands\tree.py", line 1089, in wrapper
    await self._call(interaction)
  File "C:\Users\WalkenNi\AppData\Local\Packages\PythonSoftwareFoundation.Python.3.11_qbz5n2kfra8p0\LocalCache\local-packages\Python311\site-packages\discord\app_commands\tree.py", line 1221, in _call
    command, options = self._get_app_command_options(data)
                       ^^^^^^^^^^^^^^^^^^^^^^^^^^^^^^^^^^^
  File "C:\Users\WalkenNi\AppData\Local\Packages\PythonSoftwareFoundation.Python.3.11_qbz5n2kfra8p0\LocalCache\local-packages\Python311\site-packages\discord\app_commands\tree.py", line 1125, in _get_app_command_options
    raise CommandNotFound(name, parents)
discord.app_commands.errors.CommandNotFound: Application command 'channel_message' not found
2023-08-25 10:43:05 [ERROR]: Ignoring exception in command tree
Traceback (most recent call last):
  File "C:\Users\WalkenNi\AppData\Local\Packages\PythonSoftwareFoundation.Python.3.11_qbz5n2kfra8p0\LocalCache\local-packages\Python311\site-packages\discord\app_commands\tree.py", line 1089, in wrapper
    await self._call(interaction)
  File "C:\Users\WalkenNi\AppData\Local\Packages\PythonSoftwareFoundation.Python.3.11_qbz5n2kfra8p0\LocalCache\local-packages\Python311\site-packages\discord\app_commands\tree.py", line 1221, in _call
    command, options = self._get_app_command_options(data)
                       ^^^^^^^^^^^^^^^^^^^^^^^^^^^^^^^^^^^
  File "C:\Users\WalkenNi\AppData\Local\Packages\PythonSoftwareFoundation.Python.3.11_qbz5n2kfra8p0\LocalCache\local-packages\Python311\site-packages\discord\app_commands\tree.py", line 1125, in _get_app_command_options
    raise CommandNotFound(name, parents)
discord.app_commands.errors.CommandNotFound: Application command 'channel_message' not found
2023-08-25 10:43:09 [ERROR]: Ignoring exception in command tree
Traceback (most recent call last):
  File "C:\Users\WalkenNi\AppData\Local\Packages\PythonSoftwareFoundation.Python.3.11_qbz5n2kfra8p0\LocalCache\local-packages\Python311\site-packages\discord\app_commands\tree.py", line 1089, in wrapper
    await self._call(interaction)
  File "C:\Users\WalkenNi\AppData\Local\Packages\PythonSoftwareFoundation.Python.3.11_qbz5n2kfra8p0\LocalCache\local-packages\Python311\site-packages\discord\app_commands\tree.py", line 1221, in _call
    command, options = self._get_app_command_options(data)
                       ^^^^^^^^^^^^^^^^^^^^^^^^^^^^^^^^^^^
  File "C:\Users\WalkenNi\AppData\Local\Packages\PythonSoftwareFoundation.Python.3.11_qbz5n2kfra8p0\LocalCache\local-packages\Python311\site-packages\discord\app_commands\tree.py", line 1125, in _get_app_command_options
    raise CommandNotFound(name, parents)
discord.app_commands.errors.CommandNotFound: Application command 'wb_new_entry' not found
2023-08-25 12:17:41 [INFO]: Shard ID None has successfully RESUMED session 40c0457069e5a12b67ac0afa3b4e74d9.
